Traceback (most recent call last):
  File "/home/jfhlewyee/anaconda3/envs/jb/lib/python3.13/site-packages/jupyter_cache/executors/utils.py", line 58, in single_nb_execution
    executenb(
    ~~~~~~~~~^
        nb,
        ^^^
    ...<4 lines>...
        **kwargs,
        ^^^^^^^^^
    )
    ^
  File "/home/jfhlewyee/anaconda3/envs/jb/lib/python3.13/site-packages/nbclient/client.py", line 1319, in execute
    return NotebookClient(nb=nb, resources=resources, km=km, **kwargs).execute()
           ~~~~~~~~~~~~~~~~~~~~~~~~~~~~~~~~~~~~~~~~~~~~~~~~~~~~~~~~~~~~~~~~~~~^^
  File "/home/jfhlewyee/anaconda3/envs/jb/lib/python3.13/site-packages/jupyter_core/utils/__init__.py", line 165, in wrapped
    return loop.run_until_complete(inner)
           ~~~~~~~~~~~~~~~~~~~~~~~^^^^^^^
  File "/home/jfhlewyee/anaconda3/envs/jb/lib/python3.13/asyncio/base_events.py", line 720, in run_until_complete
    return future.result()
           ~~~~~~~~~~~~~^^
  File "/home/jfhlewyee/anaconda3/envs/jb/lib/python3.13/site-packages/nbclient/client.py", line 709, in async_execute
    await self.async_execute_cell(
        cell, index, execution_count=self.code_cells_executed + 1
    )
  File "/home/jfhlewyee/anaconda3/envs/jb/lib/python3.13/site-packages/nbclient/client.py", line 1062, in async_execute_cell
    await self._check_raise_for_error(cell, cell_index, exec_reply)
  File "/home/jfhlewyee/anaconda3/envs/jb/lib/python3.13/site-packages/nbclient/client.py", line 918, in _check_raise_for_error
    raise CellExecutionError.from_cell_and_msg(cell, exec_reply_content)
nbclient.exceptions.CellExecutionError: An error occurred while executing the following cell:
------------------
import yaml
import numpy as np

benchmark = "P30-10"
nof = "GNOFm25"
ncwo = "ncwo1"
path = "../{}/{}/{}/".format(ncwo, benchmark, nof)
file = open(path + '{}-{}-{}.yaml'.format(benchmark, nof, ncwo), 'r')
data = yaml.safe_load(file)
------------------


[0;31m---------------------------------------------------------------------------[0m
[0;31mFileNotFoundError[0m                         Traceback (most recent call last)
Cell [0;32mIn[1], line 8[0m
[1;32m      6[0m ncwo [38;5;241m=[39m [38;5;124m"[39m[38;5;124mncwo1[39m[38;5;124m"[39m
[1;32m      7[0m path [38;5;241m=[39m [38;5;124m"[39m[38;5;124m../[39m[38;5;132;01m{}[39;00m[38;5;124m/[39m[38;5;132;01m{}[39;00m[38;5;124m/[39m[38;5;132;01m{}[39;00m[38;5;124m/[39m[38;5;124m"[39m[38;5;241m.[39mformat(ncwo, benchmark, nof)
[0;32m----> 8[0m file [38;5;241m=[39m [38;5;28;43mopen[39;49m[43m([49m[43mpath[49m[43m [49m[38;5;241;43m+[39;49m[43m [49m[38;5;124;43m'[39;49m[38;5;132;43;01m{}[39;49;00m[38;5;124;43m-[39;49m[38;5;132;43;01m{}[39;49;00m[38;5;124;43m-[39;49m[38;5;132;43;01m{}[39;49;00m[38;5;124;43m.yaml[39;49m[38;5;124;43m'[39;49m[38;5;241;43m.[39;49m[43mformat[49m[43m([49m[43mbenchmark[49m[43m,[49m[43m [49m[43mnof[49m[43m,[49m[43m [49m[43mncwo[49m[43m)[49m[43m,[49m[43m [49m[38;5;124;43m'[39;49m[38;5;124;43mr[39;49m[38;5;124;43m'[39;49m[43m)[49m
[1;32m      9[0m data [38;5;241m=[39m yaml[38;5;241m.[39msafe_load(file)

File [0;32m~/anaconda3/envs/jb/lib/python3.13/site-packages/IPython/core/interactiveshell.py:324[0m, in [0;36m_modified_open[0;34m(file, *args, **kwargs)[0m
[1;32m    317[0m [38;5;28;01mif[39;00m file [38;5;129;01min[39;00m {[38;5;241m0[39m, [38;5;241m1[39m, [38;5;241m2[39m}:
[1;32m    318[0m     [38;5;28;01mraise[39;00m [38;5;167;01mValueError[39;00m(
[1;32m    319[0m         [38;5;124mf[39m[38;5;124m"[39m[38;5;124mIPython won[39m[38;5;124m'[39m[38;5;124mt let you open fd=[39m[38;5;132;01m{[39;00mfile[38;5;132;01m}[39;00m[38;5;124m by default [39m[38;5;124m"[39m
[1;32m    320[0m         [38;5;124m"[39m[38;5;124mas it is likely to crash IPython. If you know what you are doing, [39m[38;5;124m"[39m
[1;32m    321[0m         [38;5;124m"[39m[38;5;124myou can use builtins[39m[38;5;124m'[39m[38;5;124m open.[39m[38;5;124m"[39m
[1;32m    322[0m     )
[0;32m--> 324[0m [38;5;28;01mreturn[39;00m [43mio_open[49m[43m([49m[43mfile[49m[43m,[49m[43m [49m[38;5;241;43m*[39;49m[43margs[49m[43m,[49m[43m [49m[38;5;241;43m*[39;49m[38;5;241;43m*[39;49m[43mkwargs[49m[43m)[49m

[0;31mFileNotFoundError[0m: [Errno 2] No such file or directory: '../ncwo1/P30-10/GNOFm25/P30-10-GNOFm25-ncwo1.yaml'

